<?xml version="1.0" ?>
<robot xmlns:xacro="http://www.ros.org/wiki/xacro">
 
 
 <joint name="Root_joint" type="fixed">
    <parent link="base_link"/>
    <child link="Diff_Bot__link_0"/>
    <origin xyz="0 0 0" rpy="0 0 0"/>
  </joint>
  
  
  <joint name="foot_joint" type="fixed">
    <parent link="base_link"/>
    <child link="base_footprint"/>
    <origin xyz="0 0 0" rpy="0 0 0"/>
  </joint>
  
  
  <joint name="Diff_Bot__link_0_JOINT_1" type="continuous">
    <parent link="base_link"/>
    <child link="Diff_Bot__link_1"/>
    <origin xyz="1.20761  1.01943 -0.07838" rpy="1.5707 0 0"/>
    <axis xyz="0 0 1"/>
  </joint>
  
  
  <joint name="Diff_Bot__link_0_JOINT_2" type="continuous">
    <parent link="base_link"/>
    <child link="Diff_Bot__link_1_clone"/>
    <origin xyz="1.20761 -1.00867 -0.07838" rpy="1.5707 0     0"/>
    <axis xyz="0 0 1"/>
  </joint>
  
  
  <joint name="Diff_Bot__link_0_JOINT_3" type="fixed">
    <parent link="base_link"/>
    <child link="Diff_Bot__link_2"/>
    <origin xyz="-1 0 -0.2" rpy="0 0 0"/>
  </joint>
  
  
  
  <link name="base_link">
  </link>
  
  <link name="base_footprint">
  </link>

  <link name="Diff_Bot__link_0">
    <inertial>
      <mass value="2.99117"/>
      <origin xyz="0 0 0" rpy="0 0 0"/>
      <inertia ixx="0.860724" ixy="0" ixz="0" iyy="2.16719" iyz="0" izz="2.85604"/>
    </inertial>
    <collision name="Diff_Bot__collision">
      <origin xyz="0.06283 -0.00211  0.02162" rpy="0 0 0"/>
      <geometry>
        <box size="2.88957 1.76304 0.587159"/>
      </geometry>
    </collision>
    <visual name="Diff_Bot__visual">
      <origin xyz="0.06283 -0.00211  0.02162" rpy="0 0 0"/>
      <geometry>
        <box size="2.88957 1.76304 0.587159"/>
      </geometry>
    </visual>
  </link>
  
  
  <link name="Diff_Bot__link_1">
    <inertial>
      <mass value="1"/>
      <origin xyz="0 0 0" rpy="0 0 0"/>
      <inertia ixx="0.145833" ixy="0" ixz="0" iyy="0.145833" iyz="0" izz="0.125"/>
    </inertial>
    <collision name="Diff_Bot__collision">
      <origin xyz="0 0 0" rpy="0 0 0"/>
      <geometry>
        <cylinder radius="0.3" length="0.25"/>
      </geometry>
      <mu value="2.5"/>
    </collision>
    <visual name="Diff_Bot__visual">
      <origin xyz="0 0 0" rpy="0 0 0"/>
      <geometry>
        <cylinder radius="0.3" length="0.25"/>
      </geometry>
    </visual>
  </link>
  
  <gazebo>
   <friction>
     <mu>100.0</mu>
     <mu2>100.0</mu2>
   </friction>
  </gazebo>

  <link name="Diff_Bot__link_1_clone">
    <inertial>
      <mass value="1"/>
      <origin xyz="0 0 0" rpy="0 0 0"/>
      <inertia ixx="0.145833" ixy="0" ixz="0" iyy="0.145833" iyz="0" izz="0.125"/>
    </inertial>
    <collision name="Diff_Bot__collision">
      <origin xyz="0 0 0" rpy="0 0 0"/>
      <geometry>
        <cylinder radius="0.3" length="0.25"/>
      </geometry>   
    </collision>
    <visual name="Diff_Bot__visual">
      <origin xyz="0 0 0" rpy="0 0 0"/>
      <geometry>
        <cylinder radius="0.3" length="0.25"/>
      </geometry>
    </visual>
  </link>

  <gazebo reference="Diff_Bot__link_1_clone">
    <friction>
        <mu>100.0</mu>
        <mu2>100.0</mu2>
    </friction>
   </gazebo>


  <link name="Diff_Bot__link_2">
    <inertial>
      <mass value="1"/>
      <origin xyz="0 0 0" rpy="0 0 0"/>
      <inertia ixx="0.1" ixy="0" ixz="0" iyy="0.1" iyz="0" izz="0.1"/>
      <mu value="0.001"/>
    </inertial>
    <collision name="Diff_Bot__collision">
      <origin xyz="0 0 0" rpy="0 0 0"/>
      <geometry>
        <sphere radius="0.2"/>
      </geometry>
    </collision>
    <visual name="Diff_Bot__visual1">
      <origin xyz="0 0 0" rpy="0 0 0"/>
      <geometry>
        <sphere radius="0.2"/>
      </geometry>
      <material name="red">
           <color rgba="1 0 0 1"/>
      </material>
    </visual>
  </link>
  
  <gazebo reference="Diff_Bot__link_2">
    <friction>
        <mu>0.0001</mu>
        <mu2>0.0001</mu2>
    </friction>
  </gazebo>


</robot>