<?xml version="1.0" ?>
<robot name="rugbot2">
  
  
  <joint name="Root_joint" type="fixed">
    <parent link="base_link"/>
    <child link="rugbot2__base_footprint"/>
    <origin xyz="0 0 0" rpy="0 0 0"/>
  </joint>
  <joint name="foot_joint" type="fixed">
    <parent link="base_footprint"/>
    <child link="base_link"/>
    <origin xyz="0 0 0" rpy="0 0 0"/>
  </joint>
  <joint name="rugbot2__base_footprint_JOINT_3" type="fixed">
    <parent link="base_link"/>
    <child link="rugbot2__link_0"/>
    <origin xyz="1.30761 -0.00211 -0.2" rpy="0 0 0"/>
    <axis xyz="0 0 0"/>
  </joint>
  
  <joint name="rugbot2__base_footprint_JOINT_1" type="continuous">
    <parent link="base_link"/>
    <child link="rugbot2__Diff_Bot__link_1"/>
    <origin xyz="-1.08281  1.00475 -0.12241" rpy="1.5707 0     0"/>
    <axis xyz="0 0 -1"/>
  </joint>
  
  <joint name="rugbot2__base_footprint_JOINT_2" type="continuous">
    <parent link="base_link"/>
    <child link="rugbot2__Diff_Bot__link_1_clone"/>
    <origin xyz="-1.08179 -1.01015 -0.12239" rpy="1.5707 0     0"/>
    <axis xyz="0  0 -1"/>
  </joint>
  <joint name="laser_joint" type="fixed">
    <parent link="base_link"/>
    <child link="laser"/>
    <origin xyz="1.32626 -0.04215  0.57358" rpy="0       0      0"/>
    <axis xyz="0 0 0"/>
    <limit lower="0" upper="0" effort="0" velocity="0"/>
  </joint>
  
  

  <link name="base_link">
  </link>
  <link name="base_footprint">
  </link>

  <link name="laser">
    <inertial>
      <mass value="0.00155316"/>
      <origin xyz="0 0 0" rpy="0 0 0"/>
      <inertia ixx="3.60557e-06" ixy="0" ixz="0" iyy="3.37436e-06" iyz="0" izz="3.45308e-06"/>
    </inertial>
    <collision name="rugbot.sdf__collision">
      <origin xyz="0 0 0" rpy="0 0 0"/>
      <geometry>
        <box size="0.111563 0.119301 0.66724"/>
      </geometry>
    </collision>
    <visual name="rugbot.sdf__visual">
      <origin xyz="0 0 0" rpy="0 0 0"/>
      <geometry>
        <box size="0.111563 0.119301 0.616724"/>
      </geometry>
    </visual>
  </link>

  <link name="rugbot2__base_footprint">
    <inertial>
      <mass value="3.99272"/>
      <origin xyz="-2.5097e-01 -1.0000e-05 -4.9860e-02" rpy="0 0 0"/>
      <inertia ixx="0.991312" ixy="0" ixz="0" iyy="3.04902" iyz="4.081e-05" izz="3.70729"/>
    </inertial>
    <collision name="rugbot2__base_footprint_fixed_joint_lump__Diff_Bot__collision_collision_1">
      <origin xyz="0.06283 -0.00211  0.02162" rpy="0 0 0"/>
      <geometry>
        <box size="2.88957 1.76304 0.587159"/>
      </geometry>
    </collision>
    <visual name="rugbot2__base_footprint_fixed_joint_lump__Diff_Bot__visual_visual_1">
      <origin xyz="0.06283 -0.00211  0.02162" rpy="0 0 0"/>
      <geometry>
        <box size="2.88957 1.76304 0.587159"/>
      </geometry>
    </visual>
  </link>
  
  
  <link name="rugbot2__Diff_Bot__link_1">
    <inertial>
      <mass value="1"/>
      <origin xyz="0 0 0" rpy="0 0 0"/>
      <inertia ixx="0.145833" ixy="0" ixz="0" iyy="0.145833" iyz="0" izz="0.125"/>
    </inertial>
    <collision name="rugbot2__Diff_Bot__link_1_fixed_joint_lump__Diff_Bot__collision_collision">
      <origin xyz="0 0 0" rpy="0 0 0"/>
      <geometry>
        <cylinder radius="0.3" length="0.25"/>
      </geometry>
    </collision>
    <visual name="rugbot2__Diff_Bot__link_1_fixed_joint_lump__Diff_Bot__visual_visual">
      <origin xyz="0 0 0" rpy="0 0 0"/>
      <geometry>
        <cylinder radius="0.3" length="0.25"/>
      </geometry>
    </visual>
  </link>
  
  
  <link name="rugbot2__Diff_Bot__link_1_clone">
    <inertial>
      <mass value="1"/>
      <origin xyz="0 0 0" rpy="0 0 0"/>
      <inertia ixx="0.145833" ixy="0" ixz="0" iyy="0.145833" iyz="0" izz="0.125"/>
    </inertial>
    <collision name="rugbot2__Diff_Bot__link_1_clone_fixed_joint_lump__Diff_Bot__collision_collision">
      <origin xyz="0 0 0" rpy="0 0 0"/>
      <geometry>
        <cylinder radius="0.3" length="0.25"/>
      </geometry>
    </collision>
    <visual name="rugbot2__Diff_Bot__link_1_clone_fixed_joint_lump__Diff_Bot__visual_visual">
      <origin xyz="0 0 0" rpy="0 0 0"/>
      <geometry>
        <cylinder radius="0.3" length="0.25"/>
      </geometry>
    </visual>
  </link>
  
  
  <link name="rugbot2__link_0">
    <inertial>
      <mass value="1"/>
      <origin xyz="0 0 0" rpy="0 0 0"/>
      <inertia ixx="0.1" ixy="0" ixz="0" iyy="0.1" iyz="0" izz="0.1"/>
    </inertial>
    <collision name="rugbot2__collision">
      <origin xyz="0 0 0" rpy="0 0 0"/>
      <geometry>
        <sphere radius="0.2"/>
      </geometry>
    </collision>
    <visual name="rugbot2__visual">
      <origin xyz="0 0 0" rpy="0 0 0"/>
      <geometry>
        <sphere radius="0.2"/>
      </geometry>
    </visual>
  </link>

<gazebo>
  <plugin name="differential_drive_controller" filename="libgazebo_ros_diff_drive.so">
    <!-- Plugin update rate in Hz -->
    <updateRate>100</updateRate>
    <!-- Name of left joint, defaults to `left_joint` -->
    <leftJoint>rugbot2__base_footprint_JOINT_1</leftJoint>
    <!-- Name of right joint, defaults to `right_joint` -->
    <rightJoint>rugbot2__base_footprint_JOINT_2</rightJoint>
    <!-- The distance from the center of one wheel to the other, in meters, defaults to 0.34 m -->
    <wheelSeparation>2.01304</wheelSeparation>
    <!-- Diameter of the wheels, in meters, defaults to 0.15 m -->
    <wheelDiameter>0.6</wheelDiameter>
    <!-- Wheel acceleration, in rad/s^2, defaults to 0.0 rad/s^2 -->
    <wheelAcceleration>0</wheelAcceleration>
    <!-- Maximum torque which the wheels can produce, in Nm, defaults to 5 Nm -->
    <wheelTorque>20</wheelTorque>
    <!-- Topic to receive geometry_msgs/Twist message commands, defaults to `cmd_vel` -->
    <commandTopic>cmd_vel</commandTopic>
    <!-- Topic to publish nav_msgs/Odometry messages, defaults to `odom` -->
    <odometryTopic>odom</odometryTopic>
    <!-- Odometry frame, defaults to `odom` -->
    <odometryFrame>odom</odometryFrame>
    <!-- Robot frame to calculate odometry from, defaults to `base_footprint` -->
    <robotBaseFrame>base_footprint</robotBaseFrame>
    <!-- Odometry source, 0 for ENCODER, 1 for WORLD, defaults to WORLD -->
    <odometrySource>1</odometrySource>
    <!-- Set to true to publish transforms for the wheel links, defaults to false -->
    <publishWheelTF>true</publishWheelTF>
    <!-- Set to true to publish transforms for the odometry, defaults to true -->
    <publishOdom>true</publishOdom>
    <!-- Set to true to publish sensor_msgs/JointState on /joint_states for the wheel joints, defaults to false -->
    <publishWheelJointState>true</publishWheelJointState>
    <!-- Set to true to swap right and left wheels, defaults to true -->
    <legacyMode>false</legacyMode>
  </plugin>
</gazebo>

<gazebo reference="laser">
        <sensor name="laser1" type="ray">
            <pose> 0 0 0 0 0 0 </pose>
            <visualize>true</visualize>
            <update_rate>50</update_rate>
            <ray>
                <scan>
                    <horizontal>
                        <samples>360</samples>
                        <min_angle>3.14</min_angle>
                        <max_angle>-3.14</max_angle>
                    </horizontal>
                </scan>
                <range>
                    <min>0.3</min>
                    <max>20</max>
                </range>
            </ray>
            <plugin name="gazebo_ros_head_hokuyo_controller" filename="libgazebo_ros_laser.so">
                <topicName>rugbot2/scan</topicName>
                <frameName>laser</frameName>
            </plugin>
        </sensor>
    </gazebo>
</robot>
